Traceback (most recent call last):
  File "/opt/hostedtoolcache/Python/3.11.8/x64/lib/python3.11/site-packages/jupyter_cache/executors/utils.py", line 58, in single_nb_execution
    executenb(
  File "/opt/hostedtoolcache/Python/3.11.8/x64/lib/python3.11/site-packages/nbclient/client.py", line 1314, in execute
    return NotebookClient(nb=nb, resources=resources, km=km, **kwargs).execute()
           ^^^^^^^^^^^^^^^^^^^^^^^^^^^^^^^^^^^^^^^^^^^^^^^^^^^^^^^^^^^^^^^^^^^^^
  File "/opt/hostedtoolcache/Python/3.11.8/x64/lib/python3.11/site-packages/jupyter_core/utils/__init__.py", line 165, in wrapped
    return loop.run_until_complete(inner)
           ^^^^^^^^^^^^^^^^^^^^^^^^^^^^^^
  File "/opt/hostedtoolcache/Python/3.11.8/x64/lib/python3.11/asyncio/base_events.py", line 654, in run_until_complete
    return future.result()
           ^^^^^^^^^^^^^^^
  File "/opt/hostedtoolcache/Python/3.11.8/x64/lib/python3.11/site-packages/nbclient/client.py", line 709, in async_execute
    await self.async_execute_cell(
  File "/opt/hostedtoolcache/Python/3.11.8/x64/lib/python3.11/site-packages/nbclient/client.py", line 1062, in async_execute_cell
    await self._check_raise_for_error(cell, cell_index, exec_reply)
  File "/opt/hostedtoolcache/Python/3.11.8/x64/lib/python3.11/site-packages/nbclient/client.py", line 918, in _check_raise_for_error
    raise CellExecutionError.from_cell_and_msg(cell, exec_reply_content)
nbclient.exceptions.CellExecutionError: An error occurred while executing the following cell:
------------------
# Code Section: Importing Necessary Libraries and Initializing Variables
import time
import torch
import numpy as np
import matplotlib.pyplot as plt
from particula.lagrangian import boundary, integration, collisions, particle_property, particle_pairs
from particula.activity import machine_limit
# Initializing the Torch Generator and setting the data type
seed = 1234
torch.manual_seed(seed)  # Set the seed for reproducibility
t_type = torch.float32
------------------


[0;31m---------------------------------------------------------------------------[0m
[0;31mImportError[0m                               Traceback (most recent call last)
Cell [0;32mIn[1], line 7[0m
[1;32m      5[0m [38;5;28;01mimport[39;00m [38;5;21;01mmatplotlib[39;00m[38;5;21;01m.[39;00m[38;5;21;01mpyplot[39;00m [38;5;28;01mas[39;00m [38;5;21;01mplt[39;00m
[1;32m      6[0m [38;5;28;01mfrom[39;00m [38;5;21;01mparticula[39;00m[38;5;21;01m.[39;00m[38;5;21;01mlagrangian[39;00m [38;5;28;01mimport[39;00m boundary, integration, collisions, particle_property, particle_pairs
[0;32m----> 7[0m [38;5;28;01mfrom[39;00m [38;5;21;01mparticula[39;00m[38;5;21;01m.[39;00m[38;5;21;01mactivity[39;00m [38;5;28;01mimport[39;00m machine_limit
[1;32m      8[0m [38;5;66;03m# Initializing the Torch Generator and setting the data type[39;00m
[1;32m      9[0m seed [38;5;241m=[39m [38;5;241m1234[39m

[0;31mImportError[0m: cannot import name 'machine_limit' from 'particula.activity' (/opt/hostedtoolcache/Python/3.11.8/x64/lib/python3.11/site-packages/particula/activity/__init__.py)

