Traceback (most recent call last):
  File "/opt/hostedtoolcache/Python/3.11.6/x64/lib/python3.11/site-packages/jupyter_cache/executors/utils.py", line 58, in single_nb_execution
    executenb(
  File "/opt/hostedtoolcache/Python/3.11.6/x64/lib/python3.11/site-packages/nbclient/client.py", line 1305, in execute
    return NotebookClient(nb=nb, resources=resources, km=km, **kwargs).execute()
           ^^^^^^^^^^^^^^^^^^^^^^^^^^^^^^^^^^^^^^^^^^^^^^^^^^^^^^^^^^^^^^^^^^^^^
  File "/opt/hostedtoolcache/Python/3.11.6/x64/lib/python3.11/site-packages/jupyter_core/utils/__init__.py", line 173, in wrapped
    return loop.run_until_complete(inner)
           ^^^^^^^^^^^^^^^^^^^^^^^^^^^^^^
  File "/opt/hostedtoolcache/Python/3.11.6/x64/lib/python3.11/asyncio/base_events.py", line 653, in run_until_complete
    return future.result()
           ^^^^^^^^^^^^^^^
  File "/opt/hostedtoolcache/Python/3.11.6/x64/lib/python3.11/site-packages/nbclient/client.py", line 705, in async_execute
    await self.async_execute_cell(
  File "/opt/hostedtoolcache/Python/3.11.6/x64/lib/python3.11/site-packages/nbclient/client.py", line 1058, in async_execute_cell
    await self._check_raise_for_error(cell, cell_index, exec_reply)
  File "/opt/hostedtoolcache/Python/3.11.6/x64/lib/python3.11/site-packages/nbclient/client.py", line 914, in _check_raise_for_error
    raise CellExecutionError.from_cell_and_msg(cell, exec_reply_content)
nbclient.exceptions.CellExecutionError: An error occurred while executing the following cell:
------------------
from particula.util.convert import datetime64_from_epoch_array

# convert the epoch time to datetime64
time_in_datetime64 = datetime64_from_epoch_array(epoch_time)

# plot the data
fig, ax = plt.subplots()
ax.plot(time_in_datetime64,
        data[:, 50],
        label=f'Bin {header[50]} nm',
        )
plt.xticks(rotation=45)
ax.set_xlabel("Time (epoch)")
ax.set_ylabel("Bin Concentration (#/cmÂ³)")
ax.legend()
plt.show()
fig.tight_layout()
------------------


[0;31m---------------------------------------------------------------------------[0m
[0;31mImportError[0m                               Traceback (most recent call last)
Cell [0;32mIn[6], line 1[0m
[0;32m----> 1[0m [38;5;28;01mfrom[39;00m [38;5;21;01mparticula[39;00m[38;5;21;01m.[39;00m[38;5;21;01mutil[39;00m[38;5;21;01m.[39;00m[38;5;21;01mconvert[39;00m [38;5;28;01mimport[39;00m datetime64_from_epoch_array
[1;32m      3[0m [38;5;66;03m# convert the epoch time to datetime64[39;00m
[1;32m      4[0m time_in_datetime64 [38;5;241m=[39m datetime64_from_epoch_array(epoch_time)

[0;31mImportError[0m: cannot import name 'datetime64_from_epoch_array' from 'particula.util.convert' (/opt/hostedtoolcache/Python/3.11.6/x64/lib/python3.11/site-packages/particula/util/convert.py)

