Traceback (most recent call last):
  File "/opt/hostedtoolcache/Python/3.10.13/x64/lib/python3.10/site-packages/jupyter_cache/executors/utils.py", line 58, in single_nb_execution
    executenb(
  File "/opt/hostedtoolcache/Python/3.10.13/x64/lib/python3.10/site-packages/nbclient/client.py", line 1305, in execute
    return NotebookClient(nb=nb, resources=resources, km=km, **kwargs).execute()
  File "/opt/hostedtoolcache/Python/3.10.13/x64/lib/python3.10/site-packages/jupyter_core/utils/__init__.py", line 173, in wrapped
    return loop.run_until_complete(inner)
  File "/opt/hostedtoolcache/Python/3.10.13/x64/lib/python3.10/asyncio/base_events.py", line 649, in run_until_complete
    return future.result()
  File "/opt/hostedtoolcache/Python/3.10.13/x64/lib/python3.10/site-packages/nbclient/client.py", line 705, in async_execute
    await self.async_execute_cell(
  File "/opt/hostedtoolcache/Python/3.10.13/x64/lib/python3.10/site-packages/nbclient/client.py", line 1058, in async_execute_cell
    await self._check_raise_for_error(cell, cell_index, exec_reply)
  File "/opt/hostedtoolcache/Python/3.10.13/x64/lib/python3.10/site-packages/nbclient/client.py", line 914, in _check_raise_for_error
    raise CellExecutionError.from_cell_and_msg(cell, exec_reply_content)
nbclient.exceptions.CellExecutionError: An error occurred while executing the following cell:
------------------
# set the parent directory of the data folder, for now this is the same as the
# current working directory, but this can be a completely different path
#
# imports os to get the current working directory
import os
from particula.data.tests.example_data.get_example_data import get_data_folder

current_path = os.getcwd()
print('Current path for this script:')
# print the path from particula/ onwards
print(current_path.split('GitHub')[1])

path = get_data_folder()
print('Path to data folder:')
print(path.split('GitHub')[1])
------------------

----- stdout -----
Current path for this script:
------------------

[0;31m---------------------------------------------------------------------------[0m
[0;31mIndexError[0m                                Traceback (most recent call last)
Cell [0;32mIn[2], line 11[0m
[1;32m      9[0m [38;5;28mprint[39m([38;5;124m'[39m[38;5;124mCurrent path for this script:[39m[38;5;124m'[39m)
[1;32m     10[0m [38;5;66;03m# print the path from particula/ onwards[39;00m
[0;32m---> 11[0m [38;5;28mprint[39m([43mcurrent_path[49m[38;5;241;43m.[39;49m[43msplit[49m[43m([49m[38;5;124;43m'[39;49m[38;5;124;43mGitHub[39;49m[38;5;124;43m'[39;49m[43m)[49m[43m[[49m[38;5;241;43m1[39;49m[43m][49m)
[1;32m     13[0m path [38;5;241m=[39m get_data_folder()
[1;32m     14[0m [38;5;28mprint[39m([38;5;124m'[39m[38;5;124mPath to data folder:[39m[38;5;124m'[39m)

[0;31mIndexError[0m: list index out of range

